Workbook

Sheet wrd_pricetater_flex_type_summar
A1: TIME PERIOD = 1 WEEK, Rate = TOU 3 | O1: CAPEX => | P1: 120559.67
A2: Season | B2: Flexibility Type | C2: Num Flexible Trains | D2: Total Operational Cost | E2: Total Water Production (m3) | F2: LCOW ($/m3) | G2: Total Energy Cost | H2: Fixed Demand Cost | I2: Variable Demand Cost | J2: Total Elec. Cost | K2: Total Feed Cost | L2: Total Brine Cost | M2: Total Chemical Cost | N2: Total Replacement Cost | O2: Total Demand Response Revenue | P2: Total Cost | Q2: Maximum Power | R2: Energy Capacity | S2: Power Capacity | T2: LVOF | U2: Charge Energy Capacity | V2: Charge Power Capacity
A3: winter | B3: no_flex | C3: 0 | D3: =J3+K3+L3+M3+N3 -> 112555.16 | E3: 282179.67 | F3: 0.82464177 | G3: 18242.546 | H3: 4851.7229 | I3: 2606.3792 | J3: 25700.648 | K3: 50843.184 | L3: 15303.798 | M3: 19297.53 | N3: 1410 | O3: 0 | P3: =D3+$P$1 -> 233114.83 | Q3: 1101.6749 | R3: 0 | S3: 0 | T3: 0
A4: summer | B4: no_flex | C4: 0 | D4: =J4+K4+L4+M4+N4 -> 121507.92 | E4: 282179.67 | F4: 0.85636894 | G4: 20627.431 | H4: 4930.8542 | I4: 9095.1263 | J4: 34653.412 | K4: 50843.184 | L4: 15303.798 | M4: 19297.53 | N4: 1410 | O4: 0 | P4: =D4+$P$1 -> 242067.6 | Q4: 1101.6749 | R4: 0 | S4: 0 | T4: 0
K5: =K4+L4+M4 -> 85444.513
A6: winter | B6: rr | C6: 0 | D6: =J6+K6+L6+M6+N6 -> 112135.07 | E6: 282179.67 | F6: 0.82463326 | G6: 18240.841 | H6: 4851.2693 | I6: 2606.1355 | J6: 25698.246 | K6: 50843.184 | L6: 15303.798 | M6: 19297.53 | N6: 992.31071 | O6: 0 | P6: =D6+$P$1 -> 232694.74 | Q6: 1101.5719 | R6: 0 | S6: 0 | T6: 0
A7: summer | B7: rr | C7: 0 | D7: =J7+K7+L7+M7+N7 -> 121097.94 | E7: 282179.67 | F7: 0.85639624 | G7: 20632.008 | H7: 4931.9487 | I7: 9097.1451 | J7: 34661.102 | K7: 50843.187 | L7: 15303.806 | M7: 19297.531 | N7: 992.31071 | O7: 0 | P7: =D7+$P$1 -> 241657.61 | Q7: 1101.9195 | R7: 0 | S7: 0 | T7: 0
A9: winter | B9: flow | C9: 0 | D9: =J9+K9+L9+M9+N9 -> 112171.66 | E9: 282179.67 | F9: 0.82476294 | G9: 18266.816 | H9: 4858.1775 | I9: 2609.8466 | J9: 25734.84 | K9: 50843.184 | L9: 15303.798 | M9: 19297.53 | N9: 992.31071 | O9: 0 | P9: =D9+$P$1 -> 232731.34 | Q9: 1103.1405 | R9: 0 | S9: 0 | T9: 0
A10: summer | B10: flow | C10: 0 | D10: =J10+K10+L10+M10+N10 -> 121125.54 | E10: 282181.81 | F10: 0.85648756 | G10: 20646.853 | H10: 4935.5484 | I10: 9103.7848 | J10: 34686.186 | K10: 50844.053 | L10: 15305.213 | M10: 19297.777 | N10: 992.31071 | O10: 0 | P10: =D10+$P$1 -> 241685.21 | Q10: 1102.7237 | R10: 0 | S10: 0 | T10: 0
A12: winter | B12: both | C12: 0 | D12: =J12+K12+L12+M12+N12 -> 112135.07 | E12: 282179.67 | F12: 0.82463326 | G12: 18240.841 | H12: 4851.2693 | I12: 2606.1355 | J12: 25698.246 | K12: 50843.184 | L12: 15303.798 | M12: 19297.53 | N12: 992.31071 | O12: 0 | P12: =D12+$P$1 -> 232694.74 | Q12: 1101.5719 | R12: 0 | S12: 0 | T12: 0
A13: summer | B13: both | C13: 0 | D13: =J13+K13+L13+M13+N13 -> 119603.36 | E13: 282179.67 | F13: 0.85109969 | G13: 20424.332 | H13: 5117.5665 | I13: 7308.5386 | J13: 32850.437 | K13: 50924.339 | L13: 15521.902 | M13: 19314.37 | N13: 992.31071 | O13: 0 | P13: =D13+$P$1 -> 240163.03 | Q13: 1143.3911 | R13: 5393.7865 | S13: 215.75146 | T13: 0.33425014
A15: winter | B15: no_flex | C15: 1 | D15: 112765.52 | E15: 282322.95 | F15: 0.82996266 | G15: 18232.263 | H15: 6458.8654 | I15: 2586.4982 | J15: 27277.627 | K15: 50869 | L15: 15311.569 | M15: 19307.329 | N15: 994.09651 | O15: 0 | P15: 234317.51 | Q15: 1466.6068 | R15: 0 | S15: 0 | T15: 0
A16: summer | B16: no_flex | C16: 1 | D16: 120212.88 | E16: 282179.67 | F16: 0.85677634 | G16: 20695.86 | H16: 4947.2118 | I16: 9125.2983 | J16: 34768.37 | K16: 50843.184 | L16: 15303.798 | M16: 19297.53 | N16: 992.31071 | O16: 0 | P16: 241764.87 | Q16: 1105.3296 | R16: 0
A18: winter | B18: no_flex | C18: 2 | D18: =J18+K18+L18+M18+N18 -> 112730.23 | E18: 282179.67 | F18: 0.82674241 | G18: 18663.29 | H18: 4963.6224 | I18: 2666.4924 | J18: 26293.405 | K18: 50843.184 | L18: 15303.798 | M18: 19297.53 | N18: 992.31071 | O18: 0 | P18: =D18+$P$1 -> 233289.9 | Q18: 1127.0838 | R18: 0 | S18: 0 | T18: 0
A19: summer | B19: no_flex | C19: 2 | D19: =J19+K19+L19+M19+N19 -> 118976.38 | E19: 282179.67 | F19: 0.84881345 | G19: 19987.388 | H19: 6536.1025 | I19: 5997.915 | J19: 32521.405 | K19: 50843.184 | L19: 15303.798 | M19: 19297.53 | N19: 1010.4627 | O19: 0 | P19: =D19+$P$1 -> 239536.05 | Q19: 1460.3272 | R19: 17682.54 | S19: 148.59277 | T19: 0.12159212
K20: =K19+L19+M19 -> 85444.513
A21: winter | B21: flow | C21: 2
A22: summer | B22: flow | C22: 2 | D22: =J22+K22+L22+M22+N22 -> 119071.82 | E22: 282179.67 | F22: 0.84915167 | G22: 20001.759 | H22: 6545.6854 | I22: 6069.3992 | J22: 32616.844 | K22: 50843.184 | L22: 15303.798 | M22: 19297.53 | N22: 1010.4627 | O22: 0 | P22: =D22+$P$1 -> 239631.49 | Q22: 1462.4682 | R22: 17686.324 | S22: 149.8841 | T22: 0.11616994
A24: winter | B24: both | C24: 2 | D24: =J24+K24+L24+M24+N24 -> 112730.23 | E24: 282179.67 | F24: 0.82674242 | G24: 18663.29 | H24: 4963.6225 | I24: 2666.4924 | J24: 26293.405 | K24: 50843.185 | L24: 15303.802 | M24: 19297.531 | N24: 992.31071 | O24: 0 | P24: =D24+$P$1 -> 233289.91 | Q24: 1127.0838 | R24: 0 | S24: 0 | T24: 0
A25: summer | B25: both | C25: 2 | D25: =J25+K25+L25+M25+N25 -> 117782.21 | E25: 282179.67 | F25: 0.84310254 | G25: 19840.537 | H25: 5280.6331 | I25: 4877.4899 | J25: 29998.66 | K25: 51077.136 | L25: 15932.544 | M25: 19346.076 | N25: 1427.7917 | O25: 0 | P25: =D25+$P$1 -> 238341.88 | Q25: 1179.8242 | R25: 12780.013 | S25: 511.20052 | T25: 0.18120426 | U25: 11081.319 | V25: 77.491739
A27: winter | B27: no_flex | C27: 4 | D27: =J27+K27+L27+M27+N27 -> 112734.69 | E27: 282179.67 | F27: 0.82675822 | G27: 18666.457 | H27: 4964.4646 | I27: 2666.9448 | J27: 26297.866 | K27: 50843.184 | L27: 15303.798 | M27: 19297.53 | N27: 992.31071 | O27: 0 | P27: =D27+$P$1 -> 233294.36 | Q27: 1127.275 | R27: 0 | S27: 0 | T27: 0
A28: summer | B28: no_flex | C28: 4 | D28: =J28+K28+L28+M28+N28 -> 119012.76 | E28: 282179.67 | F28: 0.84894239 | G28: 20022.628 | H28: 6537.0412 | I28: 5998.0824 | J28: 32557.751 | K28: 50843.194 | L28: 15303.824 | M28: 19297.532 | N28: 1010.4627 | O28: 0 | P28: =D28+$P$1 -> 239572.44 | Q28: 1460.5369 | R28: 20030.046 | S28: 178.83969 | T28: 0.10552705
A30: winter | B30: both | C30: 4 | D30: =J30+K30+L30+M30+N30 -> 113152.37 | E30: 282179.67 | F30: 0.8267582 | G30: 18666.453 | H30: 4964.4637 | I30: 2666.9443 | J30: 26297.861 | K30: 50843.184 | L30: 15303.799 | M30: 19297.531 | N30: 1410 | O30: 0 | P30: =D30+$P$1 -> 233712.05 | Q30: 1127.2748 | R30: 0 | S30: 0 | T30: 0
A31: summer | B31: both | C31: 4 | D31: =J31+K31+L31+M31+N31 -> 117790.42 | E31: 282179.67 | F31: 0.84310254 | G31: 19840.537 | H31: 5280.6331 | I31: 4877.4899 | J31: 29998.66 | K31: 51077.136 | L31: 15932.544 | M31: 19346.076 | N31: 1436 | O31: 0 | P31: =D31+$P$1 -> 238350.09 | Q31: 1179.8242 | R31: 12780.013 | S31: 511.20052 | T31: 0.18120426 | U31: 11081.319 | V31: 77.491739
A32: summer | B32: both | C32: 4 | D32: =J32+K32+L32+M32+N32 -> 118576.08 | E32: 282179.67 | F32: 0.84579333 | G32: 19619.108 | H32: 6176.7328 | I32: 1.4361985e-05 | J32: 25795.841 | K32: 50989.945 | L32: 20356.552 | M32: 19971.362 | N32: 1462.378 | O32: 0 | P32: =D32+$P$1 -> 239135.75 | Q32: 1380.0351 | R32: 33615.944 | S32: 908.53901 | T32: 0.045273803 | U32: 36375.166 | V32: 277.67302
A33: No Shutdowns - 5 Shutdowns | D33: =D31-D32 -> -785.6629 | E33: =E31-E32 -> -2.4971087e-08 | F33: =F31-F32 -> -0.0026907854 | G33: =G31-G32 -> 221.42921 | H33: =H31-H32 -> -896.09976 | I33: =I31-I32 -> 4877.4899 | J33: =J31-J32 -> 4202.8194 | K33: =K31-K32 -> 87.190675 | ... N33: =N31-N32 -> -26.377955 | O33: =O32-O31 -> 0 | P33: =P32-P31 -> 785.6629 | Q33: =Q32-Q31 -> 200.21087 | R33: =R32-R31 -> 20835.931 | S33: =S32-S31 -> 397.3385 | T33: =T32-T31 -> -0.13593046 | U33: =U32-U31 -> 25293.847 | V33: =V32-V31 -> 200.18128
A35: TOU 3 2026
A36: winter | B36: no_flex | C36: 0 | D36: =J36+K36+L36+M36+N36 -> 116993.32 | E36: 282190.86 | F36: 0.84033715 | G36: 21182.959 | H36: 6486.2597 | I36: 2466.3619 | J36: 30135.581 | K36: 50845.2 | L36: 15304.405 | M36: 19298.296 | N36: 1409.8374 | O36: 0 | P36: =D36+$P$1 -> 237552.99 | Q36: 1102.0927 | R36: 0 | U36: 15.567044 | V36: 0.092660976
A37: summer | B37: no_flex | C37: 0 | D37: =J37+K37+L37+M37+N37 -> 125900.82 | E37: 282190.86 | F37: 0.87190267 | G37: 23139.13 | H37: 6486.2597 | I37: 9417.6929 | J37: 39043.082 | K37: 50845.2 | L37: 15304.405 | M37: 19298.296 | N37: 1409.8374 | O37: 0 | P37: =D37+$P$1 -> 246460.49 | Q37: 1102.0927 | R37: 0 | U37: 15.567044 | V37: 0.092660976
A39: winter | B39: both | C39: 4 | D39: =J39+K39+L39+M39+N39 -> 116978.51 | E39: 282179.67 | F39: 0.84031801 | G39: 21174.931 | H39: 6483.8014 | I39: 2465.4272 | J39: 30124.16 | K39: 50843.185 | L39: 15303.802 | M39: 19297.531 | N39: 1409.8374 | O39: 0 | P39: =D39+$P$1 -> 237538.19 | Q39: 1101.675 | R39: 54.604983 | S39: 0.32502966 | T39: -106.83118 | U39: 0
A40: summer | B40: both | C40: 4 | D40: =J40+K40+L40+M40+N40 -> 122209.93 | E40: 282179.67 | F40: 0.85878448 | G40: 22232.996 | H40: 6892.2829 | I40: 5063.3927 | J40: 34188.671 | K40: 51137.499 | L40: 16094.769 | M40: 19358.601 | N40: 1430.394 | O40: 0 | P40: =D40+$P$1 -> 242769.61 | Q40: 1171.0808 | R40: 13170.183 | S40: 487.78457 | T40: -0.16035717 | U40: 9733.9103 | V40: 69.034825
A42: Higher Rate Even Division
A43: winter
A44: summer | B44: no_flex | C44: 0 | D44: =J44+K44+L44+M44+N44 -> 125926.94 | E44: 282190.86 | F44: 0.87199524 | G44: 23255.929 | H44: 5559.1797 | I44: 10254.094 | J44: 39069.203 | K44: 50845.2 | L44: 15304.405 | M44: 19298.296 | N44: 1409.8374 | O44: 0 | P44: =D44+$P$1 -> 246486.61 | Q44: 1102.0927 | R44: 0 | U44: 15.567044 | V44: 0.092660976
A46: winter
A47: summer | B47: both | C47: 4 | D47: =J47+K47+L47+M47+N47 -> 121548.57 | E47: 282179.67 | F47: 0.85645911 | G47: 21922.671 | H47: 5892.0772 | I47: 5494.1642 | J47: 33308.912 | K47: 51194.902 | L47: 16249.042 | M47: 19370.512 | N47: 1425.1989 | O47: 0 | P47: =D47+$P$1 -> 242108.24 | Q47: 1168.0887 | R47: 12792.664 | S47: 511.70655 | T47: -0.11339056 | U47: 7320.3797 | V47: 51.191466
A49: RTP RATE
A50: winter | B50: no_flex | C50: 0 | D50: =J50+K50+L50+M50+N50 -> 117853.99 | E50: 282179.67 | F50: 0.84490021 | G50: 23556.421 | H50: 6947.4542 | I50: 913.29199 | J50: 31417.167 | K50: 50843.184 | L50: 15303.798 | M50: 19297.53 | N50: 992.31071 | O50: 0 | P50: =D50+$P$1 -> 238413.66 | Q50: 1102.6552 | R50: 0 | S50: 0 | T50: 0
A51: summer | B51: no_flex | C51: 0 | D51: =J51+K51+L51+M51+N51 -> 182278.61 | E51: 282190.86 | F51: 1.0716887 | G51: 84096.123 | H51: 6548.9454 | I51: 4775.8074 | J51: 95420.876 | K51: 50845.2 | L51: 15304.405 | M51: 19298.296 | N51: 1409.8374 | O51: 0 | P51: =D51+$P$1 -> 302838.29 | Q51: 1101.7709 | R51: 38.493173 | S51: 0.22912603 | T51: 123.17472 | U51: 0
A53: winter | B53: both | C53: 0 | D53: =J53+K53+L53+M53+N53 -> 118024.73 | E53: 282179.67 | F53: 0.84550528 | G53: 23683.129 | H53: 6986.3696 | I53: 918.40769 | J53: 31587.907 | K53: 50843.184 | L53: 15303.798 | M53: 19297.53 | N53: 992.31071 | O53: 0 | P53: =D53+$P$1 -> 238584.4 | Q53: 1108.8316 | R53: 0 | S53: 230512.6 | T53: 1103.3673
...

Sheet Understanding DR Result
A2: Season | B2: Flexibility Type | C2: Num Flexible Trains | D2: Op Cost (No DR) | E2: Total Energy Cost | F2: Fixed Demand Cost | G2: Variable Demand Cost | H2: Total Elec. Cost | I2: Total Feed Cost | J2: Total Brine Cost | K2: Total Chemical Cost | L2: Total Demand Response Revenue
A3: NO DR, NO SHUTDOWN
A4: summer | B4: both | C4: 4 | D4: =H4+I4+J4+K4 -> 116354.42 | E4: 19840.537 | F4: 5280.6331 | G4: 4877.4899 | H4: 29998.66 | I4: 51077.136 | J4: 15932.544 | K4: 19346.076 | L4: 0
A6: NO DR, 5 SHUTDOWN | M6: Same Solution
A7: summer | B7: both | C7: 4 | D7: =H7+I7+J7+K7 -> 117113.7 | E7: 19619.108 | F7: 6176.7328 | G7: 1.4361985e-05 | H7: 25795.841 | I7: 50989.945 | J7: 20356.552 | K7: 19971.362 | L7: 0
D8: =D7-D4 -> 759.28494 | E8: =E7-E4 -> -221.42921 | F8: =F7-F4 -> 896.09976 | G8: =G7-G4 -> -4877.4899 | H8: =H7-H4 -> -4202.8194 | I8: =I7-I4 -> -87.190675 | J8: =J7-J4 -> 4424.0084 | K8: =K7-K4 -> 625.2866
A9: NO DR, 1 HR Start-Up
B10: both | C10: 4 | D10: 114153.1 | E10: 19390.341 | F10: 6212.6009 | G10: 1.2197589e-05 | H10: 25602.942 | I10: 50959.945 | J10: 17946.761 | K10: 19643.448 | L10: 0
D11: =(34653-H10-I11+wrd_pricetater_flex_type_summar!K5+L10)/34653 -> 0.1715412 | I11: =SUM(I10:K10) -> 88550.154
A12: DR, 5 SHUTDOWN
A13: summer | B13: both | C13: 4 | D13: =H13+I13+J13+K13 -> 117112.92 | E13: 19617.27 | F13: 6177.7909 | G13: 1.4897344e-05 | H13: 25795.06 | I13: 50989.945 | J13: 20356.552 | K13: 19971.362 | L13: 11020
A15: DR, 1 SHUTDOWN
A16: summer | B16: both | C16: 4 | D16: =H16+I16+J16+K16 -> 117626.33 | E16: 19403.054 | F16: 5553.2925 | G16: 4877.8861 | H16: 29834.233 | I16: 51173.67 | J16: 17123.646 | K16: 19494.782 | L16: 11020
D17: =(34653-H16-I17+wrd_pricetater_flex_type_summar!K5+L16)/34653 -> 0.38932218 | I17: =I16+J16+K16 -> 87792.099
A18: DR, 1 SHUTDOWN, 3 HR Startup | B18: both | C18: 4 | D18: =H18+I18+J18+K18 -> 118290.9 | E18: 19769.338 | F18: 6055.3448 | G18: 4869.7822 | H18: 30694.465 | I18: 50987.32 | J18: 17088.664 | K18: 19520.452 | L18: 11020
A22: Differences | J22: Most difference is the start up periods (ofc)
A23: 1 shutdown vs no shutdowns | D23: =D16-D4 -> 1271.9159 | E23: =E16-E4 -> -437.48289 | F23: =F16-F4 -> 272.65943 | G23: =G16-G4 -> 0.39617457 | H23: =H16-H4 -> -164.42729 | I23: =I16-I4 -> 96.534216 | J23: =J16-J4 -> 1191.1024 | K23: =K16-K4 -> 148.70658
A25: 5 shutdowns vs no shutdowns | D25: =D7-D4 -> 759.28494 | E25: =E7-E4 -> -221.42921 | F25: =F7-F4 -> 896.09976 | G25: =G7-G4 -> -4877.4899 | H25: =H7-H4 -> -4202.8194 | I25: =I7-I4 -> -87.190675 | J25: =J7-J4 -> 4424.0084 | K25: =K7-K4 -> 625.2866
A27: 1 shutdown vs 5 shutdowns | D27: =D16-D13 -> 513.41117 | E27: =E16-E13 -> -214.2154 | F27: =F16-F13 -> -624.49836 | G27: =G16-G13 -> 4877.8861 | H27: =H16-H13 -> 4039.1724 | I27: =I16-I13 -> 183.72487 | J27: =J16-J13 -> -3232.906 | K27: =K16-K13 -> -476.58002
A29: 3 HR shutdown vs no shutdowns | D29: =D18-D4 -> 1936.4867 | E29: =E18-E4 -> -71.198863 | F29: =F18-F4 -> 774.71175 | G29: =G18-G4 -> -7.7077004 | H29: =H18-H4 -> 695.80519 | I29: =I18-I4 -> -89.815675 | J29: =J18-J4 -> 1156.1204 | K29: =K18-K4 -> 174.37685
A31: 2 HR vs. 3 HR Shutdown | D31: =D16-D18 -> -664.57085 | E31: =E16-E18 -> -366.28403 | F31: =F16-F18 -> -502.05232 | G31: =G16-G18 -> 8.103875 | H31: =H16-H18 -> -860.23248 | I31: =I16-I18 -> 186.34989 | J31: =J16-J18 -> 34.981998 | K31: =K16-K18 -> -25.670264

Sheet SA - Start-Up Cost
G1: 121507.92 | M1: 34653.412
A2: BRINE COST DURING STARTUP | B2: Rate Structure | C2: Shutdowns | D2: Season | E2: Flexibility Type | F2: Num Flexible Trains | G2: Total Operational Cost | H2: Total Water Production (m3) | I2: LCOW ($/m3) | J2: Total Energy Cost | K2: Fixed Demand Cost | L2: Variable Demand Cost | M2: Total Elec. Cost | N2: Total Feed Cost | O2: Total Brine Cost | P2: Total Chemical Cost | Q2: Total Replacement Cost | R2: Total Demand Response Revenue | S2: Total Cost | T2: Maximum Power | U2: Energy Capacity | V2: Power Capacity | W2: LVOF | X2: Charge Energy Capacity | Y2: Charge Power Capacity | Z2: Start-Up Costs | AA2: Brine Minus Start-up Costs | AB2: Percent Savings
A3: 0 | B3: TOU3 | C3: 5 | D3: summer | E3: both | F3: 4 | G3: =M3+N3+O3+P3+Q3-R3 -> 113976.02 | H3: 282179.67 | I3: 0.82949144 | J3: 19739.41 | K3: 6280.2266 | L3: 0 | M3: 26019.636 | N3: 50944.945 | O3: 15577.282 | P3: 19971.775 | Q3: 1462.378 | R3: 0 | S3: 234065.62 | T3: 1403.1582 | U3: 34638.686 | V3: 865.96714 | W3: 0.17673834 | X3: 38493.268 | Y3: 300.72865 | Z3: =IF(A3=0,0,C3*931*(A3/0.43)) -> 0 | AA3: =O3-Z3 -> 15577.282 | AB3: =($G$1-G3)/$M$1 -> 0.21734969
A4: 0.215 | B4: TOU3 | C4: 5 | D4: summer | E4: both | F4: 4 | G4: =M4+N4+O4+P4+Q4-R4 -> 116312.84 | H4: 282179.67 | I4: 0.83777276 | J4: 19752.187 | K4: 6300.564 | L4: 0 | M4: 26052.751 | N4: 50940.911 | O4: 17895.608 | P4: 19961.188 | Q4: 1462.378 | R4: 0 | S4: 236402.44 | T4: 1407.702 | U4: 34730.952 | V4: 847.0964 | W4: 0.10898532 | X4: 38694.884 | Y4: 304.68412 | Z4: =IF(A4=0,0,C4*931*(A4/0.43)) -> 2327.5 | AA4: =O4-Z4 -> 15568.108 | AB4: =($G$1-G4)/$M$1 -> 0.14991564
A5: 0.43 | B5: TOU3 | C5: 0 | D5: summer | E5: both | F5: 4 | G5: =M5+N5+O5+P5+Q5-R5 -> 117790.42 | H5: 282179.67 | I5: 0.84310254 | J5: 19840.537 | K5: 5280.6331 | L5: 4877.4899 | M5: 29998.66 | N5: 51077.136 | O5: 15932.544 | P5: 19346.076 | Q5: 1436 | R5: 0 | S5: =G5+$P$1 -> 117790.42 | T5: 1179.8242 | U5: 12780.013 | V5: 511.20052 | W5: 0.18120426 | X5: 11081.319 | Y5: 77.491739 | Z5: =IF(A5=0,0,C5*931*(A5/0.43)) -> 0 | AA5: =O5-Z5 -> 15932.544 | AB5: =($G$1-G5)/$M$1 -> 0.10727686
A6: 0.86 | B6: TOU3 | C6: 0 | D6: summer | E6: both | F6: 4 | G6: =M6+N6+O6+P6+Q6-R6 -> 117790.42 | H6: 282179.67 | I6: 0.84310254 | J6: 19840.537 | K6: 5280.6331 | L6: 4877.4899 | M6: 29998.66 | N6: 51077.136 | O6: 15932.544 | P6: 19346.076 | Q6: 1436 | R6: 0 | S6: =G6+$P$1 -> 117790.42 | T6: 1179.8242 | U6: 12780.013 | V6: 511.20052 | W6: 0.18120426 | X6: 11081.319 | Y6: 77.491739 | Z6: =IF(A6=0,0,C6*931*(A6/0.43)) -> 0 | AA6: =O6-Z6 -> 15932.544 | AB6: =($G$1-G6)/$M$1 -> 0.10727686
A7: 1.29 | B7: TOU3 | C7: 0 | D7: summer | E7: both | F7: 4 | G7: =M7+N7+O7+P7+Q7-R7 -> 117790.42 | H7: 282179.67 | I7: 0.84310254 | J7: 19840.537 | K7: 5280.6331 | L7: 4877.4899 | M7: 29998.66 | N7: 51077.136 | O7: 15932.544 | P7: 19346.076 | Q7: 1436 | R7: 0 | S7: =G7+$P$1 -> 117790.42 | T7: 1179.8242 | U7: 12780.013 | V7: 511.20052 | W7: 0.18120426 | X7: 11081.319 | Y7: 77.491739 | Z7: =IF(A7=0,0,C7*931*(A7/0.43)) -> 0 | AA7: =O7-Z7 -> 15932.544 | AB7: =($G$1-G7)/$M$1 -> 0.10727686
A9: 0 | B9: TOU3 + DR | C9: 5 | D9: summer | E9: both | F9: 4 | G9: =M9+N9+O9+P9+Q9-R9 -> 102956.02 | H9: =H3 -> 282179.67 | I9: =I3 -> 0.82949144 | J9: =J3 -> 19739.41 | K9: =K3 -> 6280.2266 | L9: =L3 -> 0 | M9: =M3 -> 26019.636 | N9: =N3 -> 50944.945 | O9: =O3 -> 15577.282 | ... Q9: =Q3 -> 1462.378 | R9: 11020 | S9: =S3 -> 234065.62 | T9: =T3 -> 1403.1582 | U9: =U3 -> 34638.686 | V9: =V3 -> 865.96714 | W9: =W3 -> 0.17673834 | X9: =X3 -> 38493.268 | Y9: =Y3 -> 300.72865 | Z9: =IF(A9=0,0,C9*931*(A9/0.43)) -> 0 | AA9: =O9-Z9 -> 15577.282 | AB9: =($G$1-G9)/$M$1 -> 0.5353559
A10: 0.215 | B10: TOU3 + DR | C10: 5 | D10: summer | E10: both | F10: 4 | G10: =M10+N10+O10+P10+Q10-R10 -> 105292.84 | H10: =H4 -> 282179.67 | I10: =I4 -> 0.83777276 | J10: =J4 -> 19752.187 | K10: =K4 -> 6300.564 | L10: =L4 -> 0 | M10: =M4 -> 26052.751 | N10: =N4 -> 50940.911 | O10: =O4 -> 17895.608 | ... Q10: =Q4 -> 1462.378 | R10: 11020 | S10: =S4 -> 236402.44 | T10: =T4 -> 1407.702 | U10: =U4 -> 34730.952 | V10: =V4 -> 847.0964 | W10: =W4 -> 0.10898532 | X10: =X4 -> 38694.884 | Y10: =Y4 -> 304.68412 | Z10: =IF(A10=0,0,C10*931*(A10/0.43)) -> 2327.5 | AA10: =O10-Z10 -> 15568.108 | AB10: =($G$1-G10)/$M$1 -> 0.46792185
A11: 0.43 | B11: TOU3 + DR | C11: 5 | D11: summer | E11: both | F11: 4 | G11: =M11+N11+O11+P11+Q11-R11 -> 107555.3 | H11: 282179.67 | I11: 0.80673743 | J11: 19617.27 | K11: 6177.7909 | L11: 1.4897344e-05 | M11: 25795.06 | N11: 50989.945 | O11: 20356.553 | P11: 19971.362 | Q11: 1462.378 | R11: 11020 | S11: =G11+$P$1 -> 107555.3 | T11: 1380.2715 | U11: 33980.634 | V11: 943.90651 | W11: 0.36911323 | X11: 36719.73 | Y11: 278.17977 | Z11: =IF(A11=0,0,C11*931*(A11/0.43)) -> 4655 | AA11: =O11-Z11 -> 15701.553 | AB11: =($G$1-G11)/$M$1 -> 0.40263355
A12: 0.86 | B12: TOU3 + DR | C12: 1 | D12: summer | E12: both | F12: 4 | G12: =M12+N12+O12+P12+Q12-R12 -> 109004.26 | H12: 282179.67 | I12: 0.81196713 | J12: 19558.449 | K12: 5823.123 | L12: 4874.6014 | M12: 30256.174 | N12: 51073.207 | O12: 17785.319 | P12: 19473.936 | Q12: 1435.6271 | R12: 11020 | S12: 229120.62 | T12: 1301.0299 | U12: 18243.015 | V12: 200.47269 | W12: 0.60810875 | X12: 15218.2 | Y12: 197.63896 | Z12: =IF(A12=0,0,C12*931*(A12/0.43)) -> 1862 | AA12: =O12-Z12 -> 15923.319 | AB12: =($G$1-G12)/$M$1 -> 0.36082051
A13: 1.29 | B13: TOU3 + DR | C13: 1 | D13: summer | E13: both | F13: 4 | G13: =M13+N13+O13+P13+Q13-R13 -> 109934.94 | H13: 282179.67 | I13: 0.81196713 | J13: 19558.449 | K13: 5823.123 | L13: 4874.6014 | M13: 30256.174 | N13: 51073.207 | O13: =17785-Z12+Z13 -> 18716 | P13: 19473.936 | Q13: 1435.6271 | R13: 11020 | S13: 229120.62 | T13: 1301.0299 | U13: 18243.015 | V13: 200.47269 | W13: 0.60810875 | X13: 15218.2 | Y13: 197.63896 | Z13: =IF(A13=0,0,C13*931*(A13/0.43)) -> 2793 | AA13: =O13-Z13 -> 15923 | AB13: =($G$1-G13)/$M$1 -> 0.33396366
A15: 0 | B15: RTP | C15: 5 | D15: summer | E15: both | F15: 4 | G15: =M15+N15+O15+P15+Q15-R15 -> 119671.74 | H15: 282179.67 | I15: 0.84963726 | J15: 22359.429 | K15: 9372.586 | L15: 0 | M15: 31732.015 | N15: 50940.353 | O15: 15564.941 | P15: 19961.072 | Q15: 1473.3595 | R15: 0 | S15: 239750.36 | T15: 1487.5566 | U15: 36747.994 | V15: 816.62209 | W15: 1.8327058 | X15: 42963.302 | Y15: 349.29514 | Z15: =IF(A15=0,0,C15*931*(A15/0.43)) -> 0 | AA15: =O15-Z15 -> 15564.941 | AB15: =(wrd_pricetater_flex_type_summar!$D$51-G15)/wrd_pricetater_flex_type_summar!$J$51 -> 0.65611297
A16: 0.215 | B16: RTP | C16: 5 | D16: summer | E16: both | F16: 4 | G16: =M16+N16+O16+P16+Q16-R16 -> 122207.44 | H16: 282179.67 | I16: 0.85862337 | J16: 22422.409 | K16: 9246.5949 | L16: 0 | M16: 31669.004 | N16: 50981.234 | O16: 18099.531 | P16: 19984.31 | Q16: 1473.3595 | R16: 0 | S16: 242286.06 | T16: 1467.5601 | U16: 37047.6 | V16: 823.28001 | W16: 1.7494402 | X16: 43335.022 | Y16: 352.31725 | Z16: =IF(A16=0,0,C16*931*(A16/0.43)) -> 2327.5 | AA16: =O16-Z16 -> 15772.031 | AB16: =(wrd_pricetater_flex_type_summar!$D$51-G16)/wrd_pricetater_flex_type_summar!$J$51 -> 0.62953914
A17: 0.43 | B17: RTP | C17: 5 | D17: summer | E17: both | F17: 4 | G17: =M17+N17+O17+P17+Q17-R17 -> 123759.5 | H17: 282179.67 | I17: 0.86412362 | J17: 22235.129 | K17: 9205.4054 | L17: 0 | M17: 31440.535 | N17: 50868.698 | O17: 20030.701 | P17: 19946.203 | Q17: 1473.3595 | R17: 0 | S17: =G17+$P$1 -> 123759.5 | T17: 1461.0227 | U17: 37816.463 | V17: 822.09703 | W17: 1.6728297 | X17: 43765.04 | Y17: 358.72984 | Z17: =IF(A17=0,0,C17*931*(A17/0.43)) -> 4655 | AA17: =O17-Z17 -> 15375.701 | AB17: =(wrd_pricetater_flex_type_summar!$D$51-G17)/wrd_pricetater_flex_type_summar!$J$51 -> 0.61327375
A18: 0.86 | B18: RTP | C18: 5 | D18: summer | E18: both | F18: 4 | G18: =M18+N18+O18+P18+Q18-R18 -> 128510.55 | H18: 282179.67 | I18: 0.88096059 | J18: 22250.674 | K18: 9244.6814 | L18: 0 | M18: 31495.355 | N18: 50878.427 | O18: 24715.181 | P18: 19948.222 | Q18: 1473.3595 | R18: 0 | S18: 248589.17 | T18: 1467.2564 | U18: 37808.968 | V18: 821.93409 | W18: 1.547502 | X18: 43921.314 | Y18: 360.01077 | Z18: =IF(A18=0,0,C18*931*(A18/0.43)) -> 9310 | AA18: =O18-Z18 -> 15405.181 | AB18: =(wrd_pricetater_flex_type_summar!$D$51-G18)/wrd_pricetater_flex_type_summar!$J$51 -> 0.56348329
A19: 1.29 | B19: RTP | C19: 5 | D19: summer | E19: both | F19: 4 | G19: =M19+N19+O19+P19+Q19-R19 -> 133102 | H19: 282179.67 | I19: 0.89723197 | J19: 22239.846 | K19: 9215.9994 | L19: 0 | M19: 31455.845 | N19: 50871.4 | O19: 29354.629 | P19: 19946.764 | Q19: 1473.3595 | R19: 0 | S19: 253180.62 | T19: 1462.7041 | U19: 37658.738 | V19: 818.66821 | W19: 1.4317528 | X19: 43571.529 | Y19: 357.14368 | Z19: =IF(A19=0,0,C19*931*(A19/0.43)) -> 13965 | AA19: =O19-Z19 -> 15389.629 | AB19: =(wrd_pricetater_flex_type_summar!$D$51-G19)/wrd_pricetater_flex_type_summar!$J$51 -> 0.51536538

Sheet SA - Water Target
C3: Annual AF | D3: Weekly Water | E3: Plant Capacity | F3: Baseline Electricity Cost | G3: Flexible Electricity Costs | H3: Flow Cost Increase | I3: Percent Savings
B4: TWO TRAINS | C4: 8000 | D4: 188119.78 | E4: =D4/$D$9 -> 0.47659528 | F4: 23102.277 | G4: 21941.327 | H4: =(J13+K13+L13)-(J18+K18+L18) -> 227.38577 | I4: =(G4+H4-F4)/F4*100 -> -4.0410045
C5: 10000 | D5: 235149.73 | E5: =D5/$D$9 -> 0.59574409 | F5: 34228.405 | G5: 25825.975 | H5: =(J14+K14+L14)-(J19+K19+L19) -> -12815.109
C6: 12000 | D6: 282179.67 | E6: =D6/$D$9 -> 0.71489291 | F6: 34654.757 | G6: 29978.253 | H6: =(J15+K15+L15)-(J20+K20+L20) -> 1000.8859 | I6: =(G6+H6-F6)/F6*100 -> -10.606391
C7: 14000 | D7: 329209.62 | E7: =D7/$D$9 -> 0.83404173 | F7: 45897.886 | G7: 34616.141 | H7: =(J16+K16+L16)-(J21+K21+L21) -> -13034.94
B8: FOUR TRAINS | C8: 16000 | D8: 376239.56 | E8: =D8/$D$9 -> 0.95319055 | F8: 46518.362 | G8: 43908.346 | H8: =(J17+K17+L17)-(J22+K22+L22) -> 155.84142 | I8: =(G8+H8-F8)/F8*100 -> -5.2757114
B9: MAX | D9: 394716
A11: RESULTS
A12: Season | B12: Flexible | C12: Total OPEX Cost | D12: Annual Production (AF) | E12: Number of Allowed Shutdowns | F12: Total Water Production (m3) | G12: Total Cost ($) | H12: Total Energy Cost ($) | I12: Total Demand Cost ($) | J12: Total Feed Cost ($) | K12: Total Brine Cost ($) | L12: Total Chemical Cost ($) | M12: Total Electricity Cost ($) | N12: Total Replacement Cost ($) | O12: Degree of Flexibility | P12: Levelized Cost of Water ($/m3)
A13: Summer | B13: Y | C13: =N13+M13+L13+K13+J13 -> 80541.559 | D13: 8000 | E13: 10 | F13: 188119.78 | G13: 200683.7 | H13: 13644.599 | I13: 8296.7278 | J13: 33953.835 | K13: 10359.425 | L13: 12877.134 | M13: 21941.327 | N13: 1409.8374 | O13: 0 | P13: 1.0667868
A14: Summer | B14: Y | C14: =N14+M14+L14+K14+J14 -> 99135.784 | D14: 10000 | E14: 10 | F14: 235149.73 | G14: 219262.57 | H14: 16362.727 | I14: 9463.2475 | J14: 42544.121 | K14: 13222.943 | L14: 16117.547 | M14: 25825.975 | N14: 1425.1989 | O14: 0.10778443 | P14: 0.93243812
A15: Summer | B15: Y | C15: =N15+M15+L15+K15+J15 -> 117856.66 | D15: 12000 | E15: 10 | F15: 282179.67 | G15: 237975.63 | H15: 19793.406 | I15: 10184.847 | J15: 51100.151 | K15: 15994.397 | L15: 19350.851 | M15: 29978.253 | N15: 1433.0058 | O15: 0.16167665 | P15: 0.8433479
A16: Summer | B16: Y | C16: =N16+M16+L16+K16+J16 -> 135947.17 | D16: 14000 | E16: 10 | F16: 329210.46 | G16: 256066.15 | H16: 23209.552 | I16: 11406.589 | J16: 59371.758 | K16: 18001.101 | L16: 22525.164 | M16: 34616.141 | N16: 1433.0058 | O16: 0.16167665 | P16: 0.77781898
A17: Summer | B17: Y | C17: =N17+M17+L17+K17+J17 -> 159412.82 | D17: 16000 | E17: 10 | F17: 376239.56 | G17: 279542.19 | H17: 27786.289 | I17: 16122.057 | J17: 67830.923 | K17: 20512.593 | L17: 25738.343 | M17: 43908.346 | N17: 1422.6154 | O17: 0.089820359 | P17: 0.74298988
A18: Summer | B18: N | C18: =N18+M18+L18+K18+J18 -> 81475.123 | D18: 8000 | E18: 10 | F18: 188119.78 | G18: 201617.27 | H18: 13751.621 | I18: 9350.6557 | J18: 33895.456 | K18: 10202.532 | L18: 12865.02 | M18: 23102.277 | N18: 1409.8374 | O18: 0 | P18: 1.0717494
A19: Summer | B19: N | C19: =N19+M19+L19+K19+J19 -> 120337.96 | D19: 10000 | E19: 10 | F19: 279720 | G19: 240480.11 | H19: 20374.446 | I19: 13853.959 | J19: 50400 | K19: 15170.4 | L19: 19129.32 | M19: 34228.405 | N19: 1409.8374 | O19: 0 | P19: 0.85971724
A20: Summer | B20: N | C20: =N20+M20+L20+K20+J20 -> 121509.11 | D20: 12000 | E20: 10 | F20: 282179.67 | G20: 241651.25 | H20: 20628.232 | I20: 14026.525 | J20: 50843.184 | K20: 15303.798 | L20: 19297.53 | M20: 34654.757 | N20: 1409.8374 | O20: 0 | P20: 0.85637371
A21: Summer | B21: N | C21: =N21+M21+L21+K21+J21 -> 160240.69 | D21: 14000 | E21: 10 | F21: 372960.01 | G21: 280382.83 | H21: 27320.699 | I21: 18577.187 | J21: 67200.002 | K21: 20227.201 | L21: 25505.761 | M21: 45897.886 | N21: 1409.8374 | O21: 0 | P21: 0.75177719
A22: Summer | B22: N | C22: =N22+M22+L22+K22+J22 -> 161854.22 | D22: 16000 | E22: 10 | F22: 376239.56 | G22: 281996.36 | H22: 27690.037 | I22: 18828.324 | J22: 67790.912 | K22: 20405.065 | L22: 25730.041 | M22: 46518.362 | N22: 1409.8374 | O22: 0 | P22: 0.74951278
